import { describe, it, expect, vi, beforeEach } from 'vitest';

describe('Debug Minimal', () => {
  let mockFetch: any;

  beforeEach(() => {
    vi.clearAllMocks();
    mockFetch = vi.fn();
    global.fetch = mockFetch;
  });

  it('deve testar apenas o postJsonWithFallback isoladamente', async () => {
    // Importar dinamicamente para evitar problemas de hoisting
    const { AuthService } = await import('../services/authService');
    
    // Mock fetch para lan√ßar erro de rede
    mockFetch.mockImplementationOnce(() => {
      throw new Error('Network error');
    });

    try {
      // Acessar o m√©todo privado atrav√©s de reflex√£o para teste
      const postJsonWithFallback = (AuthService as any).postJsonWithFallback;
      await postJsonWithFallback('/api/auth/login', { email: 'test', password: 'test' });
      expect.fail('Deveria ter lan√ßado erro');
    } catch (error: any) {
      console.log('üîç Erro do postJsonWithFallback:', error.message);
      expect(error.message).toBe('Network error');
    }
  });

  it('deve testar o login completo com mock correto', async () => {
    // Importar dinamicamente
    const { AuthService } = await import('../services/authService');
    
    // Mock fetch para lan√ßar erro de rede
    mockFetch.mockImplementationOnce(() => {
      throw new Error('Network error');
    });

    try {
      await AuthService.login('test@example.com', 'password');
      expect.fail('Deveria ter lan√ßado erro');
    } catch (error: any) {
      console.log('üîç Erro do login:', error.message);
      console.log('üîç Stack trace:', error.stack);
      
      // Verificar se √© o erro esperado ou o bug
      if (error.message.includes('Cannot read properties of undefined')) {
        console.log('‚ùå BUG ENCONTRADO - response.headers sendo acessado quando response √© undefined');
        expect.fail(`Bug encontrado: ${error.message}`);
      } else {
        expect(error.message).toBe('Network error');
      }
    }
  });
});